[I 09:50:19.314 NotebookApp] Serving notebooks from local directory: /home/g/Documents/AdminInfo/lab_repo/LAB08
[I 09:50:19.315 NotebookApp] Jupyter Notebook 6.4.3 is running at:
[I 09:50:19.315 NotebookApp] http://localhost:8888/?token=ec4dbc4cc48726644d3ff08ea97190231034b7345588b63d
[I 09:50:19.315 NotebookApp]  or http://127.0.0.1:8888/?token=ec4dbc4cc48726644d3ff08ea97190231034b7345588b63d
[I 09:50:19.315 NotebookApp] Use Control-C to stop this server and shut down all kernels (twice to skip confirmation).
[C 09:50:19.395 NotebookApp] 
    
    To access the notebook, open this file in a browser:
        file:///home/g/.local/share/jupyter/runtime/nbserver-2763-open.html
    Or copy and paste one of these URLs:
        http://localhost:8888/?token=ec4dbc4cc48726644d3ff08ea97190231034b7345588b63d
     or http://127.0.0.1:8888/?token=ec4dbc4cc48726644d3ff08ea97190231034b7345588b63d
/usr/lib/python3.9/json/encoder.py:257: UserWarning: date_default is deprecated since jupyter_client 7.0.0. Use jupyter_client.jsonutil.json_default.
  return _iterencode(o, 0)
[W 09:50:59.891 NotebookApp] Notebook 01-Python-Basico/01-Python-Basico.ipynb is not trusted
ERROR:asyncio:Exception in callback <TaskStepMethWrapper object at 0x7f92c64b8d90>()
handle: <Handle <TaskStepMethWrapper object at 0x7f92c64b8d90>()>
Traceback (most recent call last):
  File "/usr/lib/python3.9/asyncio/events.py", line 80, in _run
    self._context.run(self._callback, *self._args)
RuntimeError: Cannot enter into task <Task pending name='Task-62' coro=<RequestHandler._execute() running at /home/g/.local/lib/python3.9/site-packages/tornado/web.py:1660> cb=[_HandlerDelegate.execute.<locals>.<lambda>() at /home/g/.local/lib/python3.9/site-packages/tornado/web.py:2326]> while another task <Task pending name='Task-61' coro=<MappingKernelManager.start_kernel() running at /usr/lib/python3.9/site-packages/notebook/services/kernels/kernelmanager.py:176> cb=[IOLoop.add_future.<locals>.<lambda>() at /home/g/.local/lib/python3.9/site-packages/tornado/ioloop.py:688]> is being executed.
/usr/lib/python3.9/sre_parse.py:440: RuntimeWarning: coroutine 'RequestHandler._execute' was never awaited
  sourcematch = source.match
RuntimeWarning: Enable tracemalloc to get the object allocation traceback
ERROR:asyncio:Task was destroyed but it is pending!
task: <Task pending name='Task-62' coro=<RequestHandler._execute() running at /home/g/.local/lib/python3.9/site-packages/tornado/web.py:1660> cb=[_HandlerDelegate.execute.<locals>.<lambda>() at /home/g/.local/lib/python3.9/site-packages/tornado/web.py:2326]>
ERROR:asyncio:Exception in callback <TaskWakeupMethWrapper object at 0x7f92c648d8e0>(<Future finis...igin\r\n\r\n'>)
handle: <Handle <TaskWakeupMethWrapper object at 0x7f92c648d8e0>(<Future finis...igin\r\n\r\n'>)>
Traceback (most recent call last):
  File "/usr/lib/python3.9/asyncio/events.py", line 80, in _run
    self._context.run(self._callback, *self._args)
RuntimeError: Cannot enter into task <Task pending name='Task-7' coro=<HTTP1ServerConnection._server_request_loop() running at /home/g/.local/lib/python3.9/site-packages/tornado/http1connection.py:823> wait_for=<Future finished result=b'GET /api/co...rigin\r\n\r\n'> cb=[IOLoop.add_future.<locals>.<lambda>() at /home/g/.local/lib/python3.9/site-packages/tornado/ioloop.py:688]> while another task <Task pending name='Task-2' coro=<KernelManager._async_start_kernel() running at /home/g/.local/lib/python3.9/site-packages/jupyter_client/manager.py:337>> is being executed.
[I 09:51:02.263 NotebookApp] Kernel started: 60e59d63-754c-499d-afc2-817a7334a3c5, name: python3
/usr/lib/python3.9/json/encoder.py:257: UserWarning: date_default is deprecated since jupyter_client 7.0.0. Use jupyter_client.jsonutil.json_default.
  return _iterencode(o, 0)
[W 09:51:24.299 NotebookApp] Notebook 01-Python-Basico/02-Python-Basico-Ejercicios.ipynb is not trusted
ERROR:asyncio:Exception in callback <TaskWakeupMethWrapper object at 0x7f92c63cdfa0>(<Future finis...igin\r\n\r\n'>)
handle: <Handle <TaskWakeupMethWrapper object at 0x7f92c63cdfa0>(<Future finis...igin\r\n\r\n'>)>
Traceback (most recent call last):
  File "/usr/lib/python3.9/asyncio/events.py", line 80, in _run
    self._context.run(self._callback, *self._args)
RuntimeError: Cannot enter into task <Task pending name='Task-8' coro=<HTTP1ServerConnection._server_request_loop() running at /home/g/.local/lib/python3.9/site-packages/tornado/http1connection.py:823> wait_for=<Future finished result=b'GET /api/co...rigin\r\n\r\n'> cb=[IOLoop.add_future.<locals>.<lambda>() at /home/g/.local/lib/python3.9/site-packages/tornado/ioloop.py:688]> while another task <Task pending name='Task-45' coro=<MappingKernelManager.start_kernel() running at /usr/lib/python3.9/site-packages/notebook/services/kernels/kernelmanager.py:176> cb=[IOLoop.add_future.<locals>.<lambda>() at /home/g/.local/lib/python3.9/site-packages/tornado/ioloop.py:695]> is being executed.
ERROR:asyncio:Exception in callback <TaskWakeupMethWrapper object at 0x7f92c63cda60>(<Future finis...igin\r\n\r\n'>)
handle: <Handle <TaskWakeupMethWrapper object at 0x7f92c63cda60>(<Future finis...igin\r\n\r\n'>)>
Traceback (most recent call last):
  File "/usr/lib/python3.9/asyncio/events.py", line 80, in _run
    self._context.run(self._callback, *self._args)
RuntimeError: Cannot enter into task <Task pending name='Task-4' coro=<HTTP1ServerConnection._server_request_loop() running at /home/g/.local/lib/python3.9/site-packages/tornado/http1connection.py:823> wait_for=<Future finished result=b'GET /kernel...rigin\r\n\r\n'> cb=[IOLoop.add_future.<locals>.<lambda>() at /home/g/.local/lib/python3.9/site-packages/tornado/ioloop.py:688]> while another task <Task pending name='Task-45' coro=<MappingKernelManager.start_kernel() running at /usr/lib/python3.9/site-packages/notebook/services/kernels/kernelmanager.py:176> cb=[IOLoop.add_future.<locals>.<lambda>() at /home/g/.local/lib/python3.9/site-packages/tornado/ioloop.py:695]> is being executed.
[I 09:51:25.028 NotebookApp] Kernel started: 27d690cd-9835-4e70-9909-d714b3c4214d, name: python3
[I 09:53:02.160 NotebookApp] Saving file at /01-Python-Basico/01-Python-Basico.ipynb
[W 09:53:02.162 NotebookApp] Notebook 01-Python-Basico/01-Python-Basico.ipynb is not trusted
[I 09:53:25.028 NotebookApp] Saving file at /01-Python-Basico/02-Python-Basico-Ejercicios.ipynb
[W 09:53:25.028 NotebookApp] Notebook 01-Python-Basico/02-Python-Basico-Ejercicios.ipynb is not trusted
[I 09:55:25.034 NotebookApp] Saving file at /01-Python-Basico/02-Python-Basico-Ejercicios.ipynb
[W 09:55:25.035 NotebookApp] Notebook 01-Python-Basico/02-Python-Basico-Ejercicios.ipynb is not trusted
[I 09:57:25.041 NotebookApp] Saving file at /01-Python-Basico/02-Python-Basico-Ejercicios.ipynb
[W 09:57:25.042 NotebookApp] Notebook 01-Python-Basico/02-Python-Basico-Ejercicios.ipynb is not trusted
[I 09:59:25.039 NotebookApp] Saving file at /01-Python-Basico/02-Python-Basico-Ejercicios.ipynb
[W 09:59:25.040 NotebookApp] Notebook 01-Python-Basico/02-Python-Basico-Ejercicios.ipynb is not trusted
[I 10:01:25.594 NotebookApp] Saving file at /01-Python-Basico/02-Python-Basico-Ejercicios.ipynb
[W 10:01:25.595 NotebookApp] Notebook 01-Python-Basico/02-Python-Basico-Ejercicios.ipynb is not trusted
[I 10:03:25.613 NotebookApp] Saving file at /01-Python-Basico/02-Python-Basico-Ejercicios.ipynb
[W 10:03:25.613 NotebookApp] Notebook 01-Python-Basico/02-Python-Basico-Ejercicios.ipynb is not trusted
[I 10:05:25.604 NotebookApp] Saving file at /01-Python-Basico/02-Python-Basico-Ejercicios.ipynb
[W 10:05:25.604 NotebookApp] Notebook 01-Python-Basico/02-Python-Basico-Ejercicios.ipynb is not trusted
[I 10:07:25.602 NotebookApp] Saving file at /01-Python-Basico/02-Python-Basico-Ejercicios.ipynb
[W 10:07:25.603 NotebookApp] Notebook 01-Python-Basico/02-Python-Basico-Ejercicios.ipynb is not trusted
[I 10:09:25.603 NotebookApp] Saving file at /01-Python-Basico/02-Python-Basico-Ejercicios.ipynb
[W 10:09:25.604 NotebookApp] Notebook 01-Python-Basico/02-Python-Basico-Ejercicios.ipynb is not trusted
[I 10:11:25.604 NotebookApp] Saving file at /01-Python-Basico/02-Python-Basico-Ejercicios.ipynb
[W 10:11:25.604 NotebookApp] Notebook 01-Python-Basico/02-Python-Basico-Ejercicios.ipynb is not trusted
[I 10:13:25.620 NotebookApp] Saving file at /01-Python-Basico/02-Python-Basico-Ejercicios.ipynb
[W 10:13:25.621 NotebookApp] Notebook 01-Python-Basico/02-Python-Basico-Ejercicios.ipynb is not trusted
[I 10:14:28.689 NotebookApp] Starting buffering for 27d690cd-9835-4e70-9909-d714b3c4214d:aa0c2a7c0ce34ad18f28ff8d42bfae3c
[I 10:14:30.026 NotebookApp] Starting buffering for 60e59d63-754c-499d-afc2-817a7334a3c5:444d6fbdb2a64127ba1262c6f380aad1
[W 10:14:34.739 NotebookApp] Notebook 02-Python-para-Analisis-de-Datos-NumPy/01-NumPy Arreglos.ipynb is not trusted
[I 10:14:35.978 NotebookApp] Kernel started: 4670a896-61b7-457d-b31b-c55d455bea09, name: python3
[W 10:14:43.522 NotebookApp] Notebook 01-Python-Basico/01-Python-Basico.ipynb is not trusted
[W 10:14:50.825 NotebookApp] Notebook 01-Python-Basico/01-Python-Basico.ipynb is not trusted
[W 10:15:00.577 NotebookApp] Notebook 01-Python-Basico/02-Python-Basico-Ejercicios.ipynb is not trusted
[I 10:15:09.685 NotebookApp] Starting buffering for 27d690cd-9835-4e70-9909-d714b3c4214d:936f476d4be2446fbd8a204b18939acd
[I 10:16:30.329 NotebookApp] Starting buffering for 4670a896-61b7-457d-b31b-c55d455bea09:7c309215b1bb4b91898672b0a41d8940
[W 10:16:30.350 NotebookApp] 404 GET /notebooks/02-Python-para-Analisis-de-Datos-NumPy/01-NumPy%20Arreglos.ipynb (127.0.0.1): No such file or directory: 02-Python-para-Analisis-de-Datos-NumPy/01-NumPy Arreglos.ipynb
[W 10:16:30.361 NotebookApp] 404 GET /notebooks/02-Python-para-Analisis-de-Datos-NumPy/01-NumPy%20Arreglos.ipynb (127.0.0.1) 12.400000ms referer=http://localhost:8888/tree/02-Python-para-Analisis-de-Datos-NumPy
[W 10:16:30.363 NotebookApp] 404 GET /api/contents/02-Python-para-Analisis-de-Datos-NumPy/01-NumPy%20Arreglos.ipynb?content=0&_=1634138074343 (127.0.0.1): No such file or directory: 02-Python-para-Analisis-de-Datos-NumPy/01-NumPy Arreglos.ipynb
[W 10:16:30.363 NotebookApp] No such file or directory: 02-Python-para-Analisis-de-Datos-NumPy/01-NumPy Arreglos.ipynb
[W 10:16:30.364 NotebookApp] 404 GET /api/contents/02-Python-para-Analisis-de-Datos-NumPy/01-NumPy%20Arreglos.ipynb?content=0&_=1634138074343 (127.0.0.1) 1.800000ms referer=http://localhost:8888/notebooks/02-Python-para-Analisis-de-Datos-NumPy/01-NumPy%20Arreglos.ipynb
[I 10:17:12.181 NotebookApp] The port 8888 is already in use, trying another port.
[I 10:17:12.182 NotebookApp] Serving notebooks from local directory: /home/g/Documents/AdminInfo/acc-python
[I 10:17:12.182 NotebookApp] Jupyter Notebook 6.4.3 is running at:
[I 10:17:12.182 NotebookApp] http://localhost:8889/?token=4bb7337c3aa491be36df9bfbd003114f1767dbb81dc1aa59
[I 10:17:12.182 NotebookApp]  or http://127.0.0.1:8889/?token=4bb7337c3aa491be36df9bfbd003114f1767dbb81dc1aa59
[I 10:17:12.182 NotebookApp] Use Control-C to stop this server and shut down all kernels (twice to skip confirmation).
[C 10:17:12.274 NotebookApp] 
    
    To access the notebook, open this file in a browser:
        file:///home/g/.local/share/jupyter/runtime/nbserver-4592-open.html
    Or copy and paste one of these URLs:
        http://localhost:8889/?token=4bb7337c3aa491be36df9bfbd003114f1767dbb81dc1aa59
     or http://127.0.0.1:8889/?token=4bb7337c3aa491be36df9bfbd003114f1767dbb81dc1aa59
/usr/lib/python3.9/json/encoder.py:257: UserWarning: date_default is deprecated since jupyter_client 7.0.0. Use jupyter_client.jsonutil.json_default.
  return _iterencode(o, 0)
[I 10:17:15.358 NotebookApp] Starting buffering for 60e59d63-754c-499d-afc2-817a7334a3c5:337992837d1c44fca6717b3c550c330b
[W 10:17:36.930 NotebookApp] Notebook 02-Python-para-Analisis-de-Datos-NumPy/01-NumPy Arreglos.ipynb is not trusted
ERROR:asyncio:Exception in callback <TaskWakeupMethWrapper object at 0x7f5639afd880>(<Future finis...igin\r\n\r\n'>)
handle: <Handle <TaskWakeupMethWrapper object at 0x7f5639afd880>(<Future finis...igin\r\n\r\n'>)>
Traceback (most recent call last):
  File "/usr/lib/python3.9/asyncio/events.py", line 80, in _run
    self._context.run(self._callback, *self._args)
RuntimeError: Cannot enter into task <Task pending name='Task-4' coro=<HTTP1ServerConnection._server_request_loop() running at /home/g/.local/lib/python3.9/site-packages/tornado/http1connection.py:823> wait_for=<Future finished result=b'GET /kernel...rigin\r\n\r\n'> cb=[IOLoop.add_future.<locals>.<lambda>() at /home/g/.local/lib/python3.9/site-packages/tornado/ioloop.py:688]> while another task <Task pending name='Task-2' coro=<KernelManager._async_start_kernel() running at /home/g/.local/lib/python3.9/site-packages/jupyter_client/manager.py:332>> is being executed.
ERROR:asyncio:Exception in callback <TaskWakeupMethWrapper object at 0x7f5639b3ffd0>(<Future finis...igin\r\n\r\n'>)
handle: <Handle <TaskWakeupMethWrapper object at 0x7f5639b3ffd0>(<Future finis...igin\r\n\r\n'>)>
Traceback (most recent call last):
  File "/usr/lib/python3.9/asyncio/events.py", line 80, in _run
    self._context.run(self._callback, *self._args)
RuntimeError: Cannot enter into task <Task pending name='Task-5' coro=<HTTP1ServerConnection._server_request_loop() running at /home/g/.local/lib/python3.9/site-packages/tornado/http1connection.py:823> wait_for=<Future finished result=b'GET /api/co...rigin\r\n\r\n'> cb=[IOLoop.add_future.<locals>.<lambda>() at /home/g/.local/lib/python3.9/site-packages/tornado/ioloop.py:688]> while another task <Task pending name='Task-2' coro=<KernelManager._async_start_kernel() running at /home/g/.local/lib/python3.9/site-packages/jupyter_client/manager.py:332>> is being executed.
[I 10:17:38.117 NotebookApp] Kernel started: 25c68c1a-bcde-4c66-8c2e-0f9baabca6c4, name: python3
/usr/lib/python3.9/json/encoder.py:257: UserWarning: date_default is deprecated since jupyter_client 7.0.0. Use jupyter_client.jsonutil.json_default.
  return _iterencode(o, 0)
[W 10:17:50.974 NotebookApp] Notebook 02-Python-para-Analisis-de-Datos-NumPy/02-Numpy Indexado y Seleccion.ipynb is not trusted
ERROR:asyncio:Exception in callback <TaskWakeupMethWrapper object at 0x7f5639a45550>(<Future finis...igin\r\n\r\n'>)
handle: <Handle <TaskWakeupMethWrapper object at 0x7f5639a45550>(<Future finis...igin\r\n\r\n'>)>
Traceback (most recent call last):
  File "/usr/lib/python3.9/asyncio/events.py", line 80, in _run
    self._context.run(self._callback, *self._args)
RuntimeError: Cannot enter into task <Task pending name='Task-7' coro=<HTTP1ServerConnection._server_request_loop() running at /home/g/.local/lib/python3.9/site-packages/tornado/http1connection.py:823> wait_for=<Future finished result=b'GET /api/co...rigin\r\n\r\n'> cb=[IOLoop.add_future.<locals>.<lambda>() at /home/g/.local/lib/python3.9/site-packages/tornado/ioloop.py:688]> while another task <Task pending name='Task-40' coro=<MappingKernelManager.start_kernel() running at /usr/lib/python3.9/site-packages/notebook/services/kernels/kernelmanager.py:176> cb=[IOLoop.add_future.<locals>.<lambda>() at /home/g/.local/lib/python3.9/site-packages/tornado/ioloop.py:695]> is being executed.
ERROR:asyncio:Exception in callback <TaskWakeupMethWrapper object at 0x7f563afd3e20>(<Future finis... GMT\r\n\r\n'>)
handle: <Handle <TaskWakeupMethWrapper object at 0x7f563afd3e20>(<Future finis... GMT\r\n\r\n'>)>
Traceback (most recent call last):
  File "/usr/lib/python3.9/asyncio/events.py", line 80, in _run
    self._context.run(self._callback, *self._args)
RuntimeError: Cannot enter into task <Task pending name='Task-1' coro=<HTTP1ServerConnection._server_request_loop() running at /home/g/.local/lib/python3.9/site-packages/tornado/http1connection.py:823> wait_for=<Future finished result=b'GET /custom...0 GMT\r\n\r\n'> cb=[IOLoop.add_future.<locals>.<lambda>() at /home/g/.local/lib/python3.9/site-packages/tornado/ioloop.py:688]> while another task <Task pending name='Task-40' coro=<MappingKernelManager.start_kernel() running at /usr/lib/python3.9/site-packages/notebook/services/kernels/kernelmanager.py:176> cb=[IOLoop.add_future.<locals>.<lambda>() at /home/g/.local/lib/python3.9/site-packages/tornado/ioloop.py:695]> is being executed.
[I 10:17:51.937 NotebookApp] Kernel started: d5ae96ab-5afd-463f-8847-4b73bb0d9a00, name: python3
[W 10:17:55.819 NotebookApp] Notebook 02-Python-para-Analisis-de-Datos-NumPy/04-Numpy Ejercicios.ipynb is not trusted
[I 10:17:56.815 NotebookApp] Kernel started: f3e90b27-f942-4e82-92ec-ea13672efdfe, name: python3
[I 10:19:38.103 NotebookApp] Saving file at /02-Python-para-Analisis-de-Datos-NumPy/01-NumPy Arreglos.ipynb
[W 10:19:38.106 NotebookApp] Notebook 02-Python-para-Analisis-de-Datos-NumPy/01-NumPy Arreglos.ipynb is not trusted
[I 10:19:51.940 NotebookApp] Saving file at /02-Python-para-Analisis-de-Datos-NumPy/02-Numpy Indexado y Seleccion.ipynb
[W 10:19:51.941 NotebookApp] Notebook 02-Python-para-Analisis-de-Datos-NumPy/02-Numpy Indexado y Seleccion.ipynb is not trusted
[I 10:19:56.912 NotebookApp] Saving file at /02-Python-para-Analisis-de-Datos-NumPy/04-Numpy Ejercicios.ipynb
[W 10:19:56.912 NotebookApp] Notebook 02-Python-para-Analisis-de-Datos-NumPy/04-Numpy Ejercicios.ipynb is not trusted
[I 10:21:51.938 NotebookApp] Saving file at /02-Python-para-Analisis-de-Datos-NumPy/02-Numpy Indexado y Seleccion.ipynb
[W 10:21:51.939 NotebookApp] Notebook 02-Python-para-Analisis-de-Datos-NumPy/02-Numpy Indexado y Seleccion.ipynb is not trusted
[I 10:21:56.806 NotebookApp] Saving file at /02-Python-para-Analisis-de-Datos-NumPy/04-Numpy Ejercicios.ipynb
[W 10:21:56.806 NotebookApp] Notebook 02-Python-para-Analisis-de-Datos-NumPy/04-Numpy Ejercicios.ipynb is not trusted
[I 10:23:13.533 NotebookApp] Starting buffering for d5ae96ab-5afd-463f-8847-4b73bb0d9a00:598ea73dcd1d42cc854f9dbf35bfb3b8
[I 10:23:17.511 NotebookApp] Saving file at /02-Python-para-Analisis-de-Datos-NumPy/04-Numpy Ejercicios.ipynb
[W 10:23:17.512 NotebookApp] Notebook 02-Python-para-Analisis-de-Datos-NumPy/04-Numpy Ejercicios.ipynb is not trusted
[I 10:23:56.807 NotebookApp] Saving file at /02-Python-para-Analisis-de-Datos-NumPy/04-Numpy Ejercicios.ipynb
[W 10:23:56.808 NotebookApp] Notebook 02-Python-para-Analisis-de-Datos-NumPy/04-Numpy Ejercicios.ipynb is not trusted
[I 10:25:56.810 NotebookApp] Saving file at /02-Python-para-Analisis-de-Datos-NumPy/04-Numpy Ejercicios.ipynb
[W 10:25:56.811 NotebookApp] Notebook 02-Python-para-Analisis-de-Datos-NumPy/04-Numpy Ejercicios.ipynb is not trusted
[I 10:27:56.804 NotebookApp] Saving file at /02-Python-para-Analisis-de-Datos-NumPy/04-Numpy Ejercicios.ipynb
[W 10:27:56.804 NotebookApp] Notebook 02-Python-para-Analisis-de-Datos-NumPy/04-Numpy Ejercicios.ipynb is not trusted
[W 10:29:52.928 NotebookApp] Notebook 02-Python-para-Analisis-de-Datos-NumPy/02-Numpy Indexado y Seleccion.ipynb is not trusted
[I 10:29:54.252 NotebookApp] Starting buffering for d5ae96ab-5afd-463f-8847-4b73bb0d9a00:55d67ceb831f48eb99c8d3d7d75e8bbf
[I 10:29:56.814 NotebookApp] Saving file at /02-Python-para-Analisis-de-Datos-NumPy/04-Numpy Ejercicios.ipynb
[W 10:29:56.815 NotebookApp] Notebook 02-Python-para-Analisis-de-Datos-NumPy/04-Numpy Ejercicios.ipynb is not trusted
[I 10:31:56.815 NotebookApp] Saving file at /02-Python-para-Analisis-de-Datos-NumPy/04-Numpy Ejercicios.ipynb
[W 10:31:56.815 NotebookApp] Notebook 02-Python-para-Analisis-de-Datos-NumPy/04-Numpy Ejercicios.ipynb is not trusted
[I 10:33:56.805 NotebookApp] Saving file at /02-Python-para-Analisis-de-Datos-NumPy/04-Numpy Ejercicios.ipynb
[W 10:33:56.805 NotebookApp] Notebook 02-Python-para-Analisis-de-Datos-NumPy/04-Numpy Ejercicios.ipynb is not trusted
[I 10:35:56.932 NotebookApp] Saving file at /02-Python-para-Analisis-de-Datos-NumPy/04-Numpy Ejercicios.ipynb
[W 10:35:56.933 NotebookApp] Notebook 02-Python-para-Analisis-de-Datos-NumPy/04-Numpy Ejercicios.ipynb is not trusted
[I 10:37:57.038 NotebookApp] Saving file at /02-Python-para-Analisis-de-Datos-NumPy/04-Numpy Ejercicios.ipynb
[W 10:37:57.039 NotebookApp] Notebook 02-Python-para-Analisis-de-Datos-NumPy/04-Numpy Ejercicios.ipynb is not trusted
[I 10:39:57.064 NotebookApp] Saving file at /02-Python-para-Analisis-de-Datos-NumPy/04-Numpy Ejercicios.ipynb
[W 10:39:57.066 NotebookApp] Notebook 02-Python-para-Analisis-de-Datos-NumPy/04-Numpy Ejercicios.ipynb is not trusted
[I 10:41:57.019 NotebookApp] Saving file at /02-Python-para-Analisis-de-Datos-NumPy/04-Numpy Ejercicios.ipynb
[W 10:41:57.020 NotebookApp] Notebook 02-Python-para-Analisis-de-Datos-NumPy/04-Numpy Ejercicios.ipynb is not trusted
[I 10:42:02.745 NotebookApp] Saving file at /02-Python-para-Analisis-de-Datos-NumPy/04-Numpy Ejercicios.ipynb
[W 10:42:02.746 NotebookApp] Notebook 02-Python-para-Analisis-de-Datos-NumPy/04-Numpy Ejercicios.ipynb is not trusted
[I 10:43:57.019 NotebookApp] Saving file at /02-Python-para-Analisis-de-Datos-NumPy/04-Numpy Ejercicios.ipynb
[W 10:43:57.020 NotebookApp] Notebook 02-Python-para-Analisis-de-Datos-NumPy/04-Numpy Ejercicios.ipynb is not trusted
[I 10:45:50.872 NotebookApp] Starting buffering for f3e90b27-f942-4e82-92ec-ea13672efdfe:3e896304307345678b72a8f3247ad9fa
[I 10:45:51.137 NotebookApp] Starting buffering for 25c68c1a-bcde-4c66-8c2e-0f9baabca6c4:b604b1fe88124484b14b4b7251342a46
[C 10:46:23.878 NotebookApp] received signal 15, stopping
[I 10:46:23.878 NotebookApp] Shutting down 3 kernels
[I 10:46:23.879 NotebookApp] Kernel shutdown: 60e59d63-754c-499d-afc2-817a7334a3c5
[I 10:46:24.083 NotebookApp] Kernel shutdown: 27d690cd-9835-4e70-9909-d714b3c4214d
[I 10:46:24.388 NotebookApp] Kernel shutdown: 4670a896-61b7-457d-b31b-c55d455bea09
[I 10:46:24.591 NotebookApp] Shutting down 0 terminals
[C 10:46:33.114 NotebookApp] received signal 15, stopping
[I 10:46:33.114 NotebookApp] Shutting down 3 kernels
[I 10:46:33.115 NotebookApp] Kernel shutdown: 25c68c1a-bcde-4c66-8c2e-0f9baabca6c4
[I 10:46:33.320 NotebookApp] Kernel shutdown: d5ae96ab-5afd-463f-8847-4b73bb0d9a00
[I 10:46:33.526 NotebookApp] Kernel shutdown: f3e90b27-f942-4e82-92ec-ea13672efdfe
[I 10:46:33.729 NotebookApp] Shutting down 0 terminals
[I 10:41:53.712 NotebookApp] Serving notebooks from local directory: /home/g/Documents/AdminInfo/acc-python
[I 10:41:53.712 NotebookApp] Jupyter Notebook 6.4.4 is running at:
[I 10:41:53.712 NotebookApp] http://localhost:8888/?token=d02b0717337dc42d784a0a274b7a598b6940d0fa6b079def
[I 10:41:53.712 NotebookApp]  or http://127.0.0.1:8888/?token=d02b0717337dc42d784a0a274b7a598b6940d0fa6b079def
[I 10:41:53.712 NotebookApp] Use Control-C to stop this server and shut down all kernels (twice to skip confirmation).
[C 10:41:53.791 NotebookApp] 
    
    To access the notebook, open this file in a browser:
        file:///home/g/.local/share/jupyter/runtime/nbserver-9671-open.html
    Or copy and paste one of these URLs:
        http://localhost:8888/?token=d02b0717337dc42d784a0a274b7a598b6940d0fa6b079def
     or http://127.0.0.1:8888/?token=d02b0717337dc42d784a0a274b7a598b6940d0fa6b079def
/usr/lib/python3.9/json/encoder.py:257: UserWarning: date_default is deprecated since jupyter_client 7.0.0. Use jupyter_client.jsonutil.json_default.
  return _iterencode(o, 0)
[W 10:45:48.081 NotebookApp] Notebook 08-Plotly y Cufflinks/01-Plotly y Cufflinks.ipynb is not trusted
ERROR:asyncio:Exception in callback <TaskWakeupMethWrapper object at 0x7f6ca760d7c0>(<Future finis...igin\r\n\r\n'>)
handle: <Handle <TaskWakeupMethWrapper object at 0x7f6ca760d7c0>(<Future finis...igin\r\n\r\n'>)>
Traceback (most recent call last):
  File "/usr/lib/python3.9/asyncio/events.py", line 80, in _run
    self._context.run(self._callback, *self._args)
RuntimeError: Cannot enter into task <Task pending name='Task-52' coro=<HTTP1ServerConnection._server_request_loop() running at /home/g/.local/lib/python3.9/site-packages/tornado/http1connection.py:823> wait_for=<Future finished result=b'GET /kernel...rigin\r\n\r\n'> cb=[IOLoop.add_future.<locals>.<lambda>() at /home/g/.local/lib/python3.9/site-packages/tornado/ioloop.py:688]> while another task <Task pending name='Task-2' coro=<KernelManager._async_start_kernel() running at /home/g/.local/lib/python3.9/site-packages/jupyter_client/manager.py:336>> is being executed.
ERROR:asyncio:Exception in callback <TaskWakeupMethWrapper object at 0x7f6ca760d970>(<Future finis...igin\r\n\r\n'>)
handle: <Handle <TaskWakeupMethWrapper object at 0x7f6ca760d970>(<Future finis...igin\r\n\r\n'>)>
Traceback (most recent call last):
  File "/usr/lib/python3.9/asyncio/events.py", line 80, in _run
    self._context.run(self._callback, *self._args)
RuntimeError: Cannot enter into task <Task pending name='Task-54' coro=<HTTP1ServerConnection._server_request_loop() running at /home/g/.local/lib/python3.9/site-packages/tornado/http1connection.py:823> wait_for=<Future finished result=b'GET /api/co...rigin\r\n\r\n'> cb=[IOLoop.add_future.<locals>.<lambda>() at /home/g/.local/lib/python3.9/site-packages/tornado/ioloop.py:688]> while another task <Task pending name='Task-2' coro=<KernelManager._async_start_kernel() running at /home/g/.local/lib/python3.9/site-packages/jupyter_client/manager.py:336>> is being executed.
[I 10:45:48.808 NotebookApp] Kernel started: 6dc8f39c-4be2-47fa-aa5f-90bcd02e61ba, name: python3
/usr/lib/python3.9/json/encoder.py:257: UserWarning: date_default is deprecated since jupyter_client 7.0.0. Use jupyter_client.jsonutil.json_default.
  return _iterencode(o, 0)
[I 10:47:16.207 NotebookApp] Saving file at /08-Plotly y Cufflinks/01-Plotly y Cufflinks.ipynb
[W 10:47:25.688 NotebookApp] Notebook 09-Visualizacion-Geografica/01-Mapas-Coropletas.ipynb is not trusted
ERROR:asyncio:Exception in callback <TaskWakeupMethWrapper object at 0x7f6cac226f10>(<Future finis...igin\r\n\r\n'>)
handle: <Handle <TaskWakeupMethWrapper object at 0x7f6cac226f10>(<Future finis...igin\r\n\r\n'>)>
Traceback (most recent call last):
  File "/usr/lib/python3.9/asyncio/events.py", line 80, in _run
    self._context.run(self._callback, *self._args)
RuntimeError: Cannot enter into task <Task pending name='Task-56' coro=<HTTP1ServerConnection._server_request_loop() running at /home/g/.local/lib/python3.9/site-packages/tornado/http1connection.py:823> wait_for=<Future finished result=b'GET /api/co...rigin\r\n\r\n'> cb=[IOLoop.add_future.<locals>.<lambda>() at /home/g/.local/lib/python3.9/site-packages/tornado/ioloop.py:688]> while another task <Task pending name='Task-172' coro=<MappingKernelManager.start_kernel() running at /usr/lib/python3.9/site-packages/notebook/services/kernels/kernelmanager.py:176> cb=[IOLoop.add_future.<locals>.<lambda>() at /home/g/.local/lib/python3.9/site-packages/tornado/ioloop.py:695]> is being executed.
[I 10:47:26.493 NotebookApp] Kernel started: 92cd7f8a-2fa2-4718-af57-265e158c36f3, name: python3
[W 10:48:48.758 NotebookApp] Notebook 09-Visualizacion-Geografica/02-Mapas Coropletas - Ejercicio.ipynb is not trusted
ERROR:asyncio:Exception in callback <TaskWakeupMethWrapper object at 0x7f6cacab49a0>(<Future finis...igin\r\n\r\n'>)
handle: <Handle <TaskWakeupMethWrapper object at 0x7f6cacab49a0>(<Future finis...igin\r\n\r\n'>)>
Traceback (most recent call last):
  File "/usr/lib/python3.9/asyncio/events.py", line 80, in _run
    self._context.run(self._callback, *self._args)
RuntimeError: Cannot enter into task <Task pending name='Task-55' coro=<HTTP1ServerConnection._server_request_loop() running at /home/g/.local/lib/python3.9/site-packages/tornado/http1connection.py:823> wait_for=<Future finished result=b'GET /api/co...rigin\r\n\r\n'> cb=[IOLoop.add_future.<locals>.<lambda>() at /home/g/.local/lib/python3.9/site-packages/tornado/ioloop.py:688]> while another task <Task pending name='Task-345' coro=<KernelManager._async_start_kernel() running at /home/g/.local/lib/python3.9/site-packages/jupyter_client/manager.py:337>> is being executed.
[I 10:48:49.271 NotebookApp] Kernel started: 7cec2379-771c-4443-a319-80ead1a10d74, name: python3
[I 10:49:26.553 NotebookApp] Saving file at /09-Visualizacion-Geografica/01-Mapas-Coropletas.ipynb
[I 10:50:49.272 NotebookApp] Saving file at /09-Visualizacion-Geografica/02-Mapas Coropletas - Ejercicio.ipynb
[W 10:50:49.273 NotebookApp] Notebook 09-Visualizacion-Geografica/02-Mapas Coropletas - Ejercicio.ipynb is not trusted
[I 10:51:07.615 NotebookApp] Starting buffering for 7cec2379-771c-4443-a319-80ead1a10d74:88a2ca5daa304a39814c7a68844fda67
[I 10:51:07.935 NotebookApp] Kernel restarted: 7cec2379-771c-4443-a319-80ead1a10d74
[I 10:51:07.970 NotebookApp] Restoring connection for 7cec2379-771c-4443-a319-80ead1a10d74:88a2ca5daa304a39814c7a68844fda67
[I 10:51:08.818 NotebookApp] Replaying 3 buffered messages
[I 10:52:49.287 NotebookApp] Saving file at /09-Visualizacion-Geografica/02-Mapas Coropletas - Ejercicio.ipynb
[W 10:52:49.291 NotebookApp] Notebook 09-Visualizacion-Geografica/02-Mapas Coropletas - Ejercicio.ipynb is not trusted
[I 10:54:49.290 NotebookApp] Saving file at /09-Visualizacion-Geografica/02-Mapas Coropletas - Ejercicio.ipynb
[W 10:54:49.293 NotebookApp] Notebook 09-Visualizacion-Geografica/02-Mapas Coropletas - Ejercicio.ipynb is not trusted
[I 10:56:49.283 NotebookApp] Saving file at /09-Visualizacion-Geografica/02-Mapas Coropletas - Ejercicio.ipynb
[W 10:56:49.285 NotebookApp] Notebook 09-Visualizacion-Geografica/02-Mapas Coropletas - Ejercicio.ipynb is not trusted
[I 11:00:49.286 NotebookApp] Saving file at /09-Visualizacion-Geografica/02-Mapas Coropletas - Ejercicio.ipynb
[W 11:00:49.290 NotebookApp] Notebook 09-Visualizacion-Geografica/02-Mapas Coropletas - Ejercicio.ipynb is not trusted
[I 11:02:49.285 NotebookApp] Saving file at /09-Visualizacion-Geografica/02-Mapas Coropletas - Ejercicio.ipynb
[W 11:02:49.289 NotebookApp] Notebook 09-Visualizacion-Geografica/02-Mapas Coropletas - Ejercicio.ipynb is not trusted
[I 11:04:49.290 NotebookApp] Saving file at /09-Visualizacion-Geografica/02-Mapas Coropletas - Ejercicio.ipynb
[W 11:04:49.293 NotebookApp] Notebook 09-Visualizacion-Geografica/02-Mapas Coropletas - Ejercicio.ipynb is not trusted
[I 11:05:13.353 NotebookApp] Starting buffering for 7cec2379-771c-4443-a319-80ead1a10d74:88a2ca5daa304a39814c7a68844fda67
[I 11:05:13.676 NotebookApp] Kernel restarted: 7cec2379-771c-4443-a319-80ead1a10d74
[I 11:05:13.709 NotebookApp] Restoring connection for 7cec2379-771c-4443-a319-80ead1a10d74:88a2ca5daa304a39814c7a68844fda67
[I 11:05:14.722 NotebookApp] Replaying 3 buffered messages
[I 11:06:49.287 NotebookApp] Saving file at /09-Visualizacion-Geografica/02-Mapas Coropletas - Ejercicio.ipynb
[W 11:06:49.291 NotebookApp] Notebook 09-Visualizacion-Geografica/02-Mapas Coropletas - Ejercicio.ipynb is not trusted
[I 11:08:49.284 NotebookApp] Saving file at /09-Visualizacion-Geografica/02-Mapas Coropletas - Ejercicio.ipynb
[W 11:08:49.287 NotebookApp] Notebook 09-Visualizacion-Geografica/02-Mapas Coropletas - Ejercicio.ipynb is not trusted
[I 11:09:49.941 NotebookApp] Starting buffering for 7cec2379-771c-4443-a319-80ead1a10d74:88a2ca5daa304a39814c7a68844fda67
[I 11:09:50.263 NotebookApp] Kernel restarted: 7cec2379-771c-4443-a319-80ead1a10d74
[I 11:09:50.323 NotebookApp] Restoring connection for 7cec2379-771c-4443-a319-80ead1a10d74:88a2ca5daa304a39814c7a68844fda67
[I 11:09:51.135 NotebookApp] Replaying 3 buffered messages
[I 11:10:49.285 NotebookApp] Saving file at /09-Visualizacion-Geografica/02-Mapas Coropletas - Ejercicio.ipynb
[W 11:10:49.288 NotebookApp] Notebook 09-Visualizacion-Geografica/02-Mapas Coropletas - Ejercicio.ipynb is not trusted
[I 11:12:49.273 NotebookApp] Saving file at /09-Visualizacion-Geografica/02-Mapas Coropletas - Ejercicio.ipynb
[W 11:12:49.275 NotebookApp] Notebook 09-Visualizacion-Geografica/02-Mapas Coropletas - Ejercicio.ipynb is not trusted
[I 11:14:49.342 NotebookApp] Saving file at /09-Visualizacion-Geografica/02-Mapas Coropletas - Ejercicio.ipynb
[W 11:14:49.345 NotebookApp] Notebook 09-Visualizacion-Geografica/02-Mapas Coropletas - Ejercicio.ipynb is not trusted
[I 11:16:49.288 NotebookApp] Saving file at /09-Visualizacion-Geografica/02-Mapas Coropletas - Ejercicio.ipynb
[W 11:16:49.292 NotebookApp] Notebook 09-Visualizacion-Geografica/02-Mapas Coropletas - Ejercicio.ipynb is not trusted
[I 11:18:49.293 NotebookApp] Saving file at /09-Visualizacion-Geografica/02-Mapas Coropletas - Ejercicio.ipynb
[I 11:20:49.286 NotebookApp] Saving file at /09-Visualizacion-Geografica/02-Mapas Coropletas - Ejercicio.ipynb
[I 11:44:30.647 NotebookApp] Starting buffering for 7cec2379-771c-4443-a319-80ead1a10d74:88a2ca5daa304a39814c7a68844fda67
[I 11:44:30.648 NotebookApp] Starting buffering for 92cd7f8a-2fa2-4718-af57-265e158c36f3:069f9b0fa476406c9e25571cfca0c003
[I 11:44:30.664 NotebookApp] Starting buffering for 6dc8f39c-4be2-47fa-aa5f-90bcd02e61ba:d0b04e88bac4474081b416c96af3390b
[C 12:02:33.298 NotebookApp] received signal 15, stopping
[I 12:02:33.302 NotebookApp] Shutting down 3 kernels
[I 12:02:33.303 NotebookApp] Kernel shutdown: 6dc8f39c-4be2-47fa-aa5f-90bcd02e61ba
[I 12:02:33.407 NotebookApp] Kernel shutdown: 92cd7f8a-2fa2-4718-af57-265e158c36f3
[I 12:02:33.409 NotebookApp] Kernel shutdown: 7cec2379-771c-4443-a319-80ead1a10d74
[I 12:02:33.411 NotebookApp] Shutting down 0 terminals
