[I 09:50:19.314 NotebookApp] Serving notebooks from local directory: /home/g/Documents/AdminInfo/lab_repo/LAB08
[I 09:50:19.315 NotebookApp] Jupyter Notebook 6.4.3 is running at:
[I 09:50:19.315 NotebookApp] http://localhost:8888/?token=ec4dbc4cc48726644d3ff08ea97190231034b7345588b63d
[I 09:50:19.315 NotebookApp]  or http://127.0.0.1:8888/?token=ec4dbc4cc48726644d3ff08ea97190231034b7345588b63d
[I 09:50:19.315 NotebookApp] Use Control-C to stop this server and shut down all kernels (twice to skip confirmation).
[C 09:50:19.395 NotebookApp] 
    
    To access the notebook, open this file in a browser:
        file:///home/g/.local/share/jupyter/runtime/nbserver-2763-open.html
    Or copy and paste one of these URLs:
        http://localhost:8888/?token=ec4dbc4cc48726644d3ff08ea97190231034b7345588b63d
     or http://127.0.0.1:8888/?token=ec4dbc4cc48726644d3ff08ea97190231034b7345588b63d
/usr/lib/python3.9/json/encoder.py:257: UserWarning: date_default is deprecated since jupyter_client 7.0.0. Use jupyter_client.jsonutil.json_default.
  return _iterencode(o, 0)
[W 09:50:59.891 NotebookApp] Notebook 01-Python-Basico/01-Python-Basico.ipynb is not trusted
ERROR:asyncio:Exception in callback <TaskStepMethWrapper object at 0x7f92c64b8d90>()
handle: <Handle <TaskStepMethWrapper object at 0x7f92c64b8d90>()>
Traceback (most recent call last):
  File "/usr/lib/python3.9/asyncio/events.py", line 80, in _run
    self._context.run(self._callback, *self._args)
RuntimeError: Cannot enter into task <Task pending name='Task-62' coro=<RequestHandler._execute() running at /home/g/.local/lib/python3.9/site-packages/tornado/web.py:1660> cb=[_HandlerDelegate.execute.<locals>.<lambda>() at /home/g/.local/lib/python3.9/site-packages/tornado/web.py:2326]> while another task <Task pending name='Task-61' coro=<MappingKernelManager.start_kernel() running at /usr/lib/python3.9/site-packages/notebook/services/kernels/kernelmanager.py:176> cb=[IOLoop.add_future.<locals>.<lambda>() at /home/g/.local/lib/python3.9/site-packages/tornado/ioloop.py:688]> is being executed.
/usr/lib/python3.9/sre_parse.py:440: RuntimeWarning: coroutine 'RequestHandler._execute' was never awaited
  sourcematch = source.match
RuntimeWarning: Enable tracemalloc to get the object allocation traceback
ERROR:asyncio:Task was destroyed but it is pending!
task: <Task pending name='Task-62' coro=<RequestHandler._execute() running at /home/g/.local/lib/python3.9/site-packages/tornado/web.py:1660> cb=[_HandlerDelegate.execute.<locals>.<lambda>() at /home/g/.local/lib/python3.9/site-packages/tornado/web.py:2326]>
ERROR:asyncio:Exception in callback <TaskWakeupMethWrapper object at 0x7f92c648d8e0>(<Future finis...igin\r\n\r\n'>)
handle: <Handle <TaskWakeupMethWrapper object at 0x7f92c648d8e0>(<Future finis...igin\r\n\r\n'>)>
Traceback (most recent call last):
  File "/usr/lib/python3.9/asyncio/events.py", line 80, in _run
    self._context.run(self._callback, *self._args)
RuntimeError: Cannot enter into task <Task pending name='Task-7' coro=<HTTP1ServerConnection._server_request_loop() running at /home/g/.local/lib/python3.9/site-packages/tornado/http1connection.py:823> wait_for=<Future finished result=b'GET /api/co...rigin\r\n\r\n'> cb=[IOLoop.add_future.<locals>.<lambda>() at /home/g/.local/lib/python3.9/site-packages/tornado/ioloop.py:688]> while another task <Task pending name='Task-2' coro=<KernelManager._async_start_kernel() running at /home/g/.local/lib/python3.9/site-packages/jupyter_client/manager.py:337>> is being executed.
[I 09:51:02.263 NotebookApp] Kernel started: 60e59d63-754c-499d-afc2-817a7334a3c5, name: python3
/usr/lib/python3.9/json/encoder.py:257: UserWarning: date_default is deprecated since jupyter_client 7.0.0. Use jupyter_client.jsonutil.json_default.
  return _iterencode(o, 0)
[W 09:51:24.299 NotebookApp] Notebook 01-Python-Basico/02-Python-Basico-Ejercicios.ipynb is not trusted
ERROR:asyncio:Exception in callback <TaskWakeupMethWrapper object at 0x7f92c63cdfa0>(<Future finis...igin\r\n\r\n'>)
handle: <Handle <TaskWakeupMethWrapper object at 0x7f92c63cdfa0>(<Future finis...igin\r\n\r\n'>)>
Traceback (most recent call last):
  File "/usr/lib/python3.9/asyncio/events.py", line 80, in _run
    self._context.run(self._callback, *self._args)
RuntimeError: Cannot enter into task <Task pending name='Task-8' coro=<HTTP1ServerConnection._server_request_loop() running at /home/g/.local/lib/python3.9/site-packages/tornado/http1connection.py:823> wait_for=<Future finished result=b'GET /api/co...rigin\r\n\r\n'> cb=[IOLoop.add_future.<locals>.<lambda>() at /home/g/.local/lib/python3.9/site-packages/tornado/ioloop.py:688]> while another task <Task pending name='Task-45' coro=<MappingKernelManager.start_kernel() running at /usr/lib/python3.9/site-packages/notebook/services/kernels/kernelmanager.py:176> cb=[IOLoop.add_future.<locals>.<lambda>() at /home/g/.local/lib/python3.9/site-packages/tornado/ioloop.py:695]> is being executed.
ERROR:asyncio:Exception in callback <TaskWakeupMethWrapper object at 0x7f92c63cda60>(<Future finis...igin\r\n\r\n'>)
handle: <Handle <TaskWakeupMethWrapper object at 0x7f92c63cda60>(<Future finis...igin\r\n\r\n'>)>
Traceback (most recent call last):
  File "/usr/lib/python3.9/asyncio/events.py", line 80, in _run
    self._context.run(self._callback, *self._args)
RuntimeError: Cannot enter into task <Task pending name='Task-4' coro=<HTTP1ServerConnection._server_request_loop() running at /home/g/.local/lib/python3.9/site-packages/tornado/http1connection.py:823> wait_for=<Future finished result=b'GET /kernel...rigin\r\n\r\n'> cb=[IOLoop.add_future.<locals>.<lambda>() at /home/g/.local/lib/python3.9/site-packages/tornado/ioloop.py:688]> while another task <Task pending name='Task-45' coro=<MappingKernelManager.start_kernel() running at /usr/lib/python3.9/site-packages/notebook/services/kernels/kernelmanager.py:176> cb=[IOLoop.add_future.<locals>.<lambda>() at /home/g/.local/lib/python3.9/site-packages/tornado/ioloop.py:695]> is being executed.
[I 09:51:25.028 NotebookApp] Kernel started: 27d690cd-9835-4e70-9909-d714b3c4214d, name: python3
[I 09:53:02.160 NotebookApp] Saving file at /01-Python-Basico/01-Python-Basico.ipynb
[W 09:53:02.162 NotebookApp] Notebook 01-Python-Basico/01-Python-Basico.ipynb is not trusted
[I 09:53:25.028 NotebookApp] Saving file at /01-Python-Basico/02-Python-Basico-Ejercicios.ipynb
[W 09:53:25.028 NotebookApp] Notebook 01-Python-Basico/02-Python-Basico-Ejercicios.ipynb is not trusted
[I 09:55:25.034 NotebookApp] Saving file at /01-Python-Basico/02-Python-Basico-Ejercicios.ipynb
[W 09:55:25.035 NotebookApp] Notebook 01-Python-Basico/02-Python-Basico-Ejercicios.ipynb is not trusted
[I 09:57:25.041 NotebookApp] Saving file at /01-Python-Basico/02-Python-Basico-Ejercicios.ipynb
[W 09:57:25.042 NotebookApp] Notebook 01-Python-Basico/02-Python-Basico-Ejercicios.ipynb is not trusted
[I 09:59:25.039 NotebookApp] Saving file at /01-Python-Basico/02-Python-Basico-Ejercicios.ipynb
[W 09:59:25.040 NotebookApp] Notebook 01-Python-Basico/02-Python-Basico-Ejercicios.ipynb is not trusted
[I 10:01:25.594 NotebookApp] Saving file at /01-Python-Basico/02-Python-Basico-Ejercicios.ipynb
[W 10:01:25.595 NotebookApp] Notebook 01-Python-Basico/02-Python-Basico-Ejercicios.ipynb is not trusted
[I 10:03:25.613 NotebookApp] Saving file at /01-Python-Basico/02-Python-Basico-Ejercicios.ipynb
[W 10:03:25.613 NotebookApp] Notebook 01-Python-Basico/02-Python-Basico-Ejercicios.ipynb is not trusted
[I 10:05:25.604 NotebookApp] Saving file at /01-Python-Basico/02-Python-Basico-Ejercicios.ipynb
[W 10:05:25.604 NotebookApp] Notebook 01-Python-Basico/02-Python-Basico-Ejercicios.ipynb is not trusted
[I 10:07:25.602 NotebookApp] Saving file at /01-Python-Basico/02-Python-Basico-Ejercicios.ipynb
[W 10:07:25.603 NotebookApp] Notebook 01-Python-Basico/02-Python-Basico-Ejercicios.ipynb is not trusted
[I 10:09:25.603 NotebookApp] Saving file at /01-Python-Basico/02-Python-Basico-Ejercicios.ipynb
[W 10:09:25.604 NotebookApp] Notebook 01-Python-Basico/02-Python-Basico-Ejercicios.ipynb is not trusted
[I 10:11:25.604 NotebookApp] Saving file at /01-Python-Basico/02-Python-Basico-Ejercicios.ipynb
[W 10:11:25.604 NotebookApp] Notebook 01-Python-Basico/02-Python-Basico-Ejercicios.ipynb is not trusted
[I 10:13:25.620 NotebookApp] Saving file at /01-Python-Basico/02-Python-Basico-Ejercicios.ipynb
[W 10:13:25.621 NotebookApp] Notebook 01-Python-Basico/02-Python-Basico-Ejercicios.ipynb is not trusted
[I 10:14:28.689 NotebookApp] Starting buffering for 27d690cd-9835-4e70-9909-d714b3c4214d:aa0c2a7c0ce34ad18f28ff8d42bfae3c
[I 10:14:30.026 NotebookApp] Starting buffering for 60e59d63-754c-499d-afc2-817a7334a3c5:444d6fbdb2a64127ba1262c6f380aad1
[W 10:14:34.739 NotebookApp] Notebook 02-Python-para-Analisis-de-Datos-NumPy/01-NumPy Arreglos.ipynb is not trusted
[I 10:14:35.978 NotebookApp] Kernel started: 4670a896-61b7-457d-b31b-c55d455bea09, name: python3
[W 10:14:43.522 NotebookApp] Notebook 01-Python-Basico/01-Python-Basico.ipynb is not trusted
[W 10:14:50.825 NotebookApp] Notebook 01-Python-Basico/01-Python-Basico.ipynb is not trusted
[W 10:15:00.577 NotebookApp] Notebook 01-Python-Basico/02-Python-Basico-Ejercicios.ipynb is not trusted
[I 10:15:09.685 NotebookApp] Starting buffering for 27d690cd-9835-4e70-9909-d714b3c4214d:936f476d4be2446fbd8a204b18939acd
[I 10:16:30.329 NotebookApp] Starting buffering for 4670a896-61b7-457d-b31b-c55d455bea09:7c309215b1bb4b91898672b0a41d8940
[W 10:16:30.350 NotebookApp] 404 GET /notebooks/02-Python-para-Analisis-de-Datos-NumPy/01-NumPy%20Arreglos.ipynb (127.0.0.1): No such file or directory: 02-Python-para-Analisis-de-Datos-NumPy/01-NumPy Arreglos.ipynb
[W 10:16:30.361 NotebookApp] 404 GET /notebooks/02-Python-para-Analisis-de-Datos-NumPy/01-NumPy%20Arreglos.ipynb (127.0.0.1) 12.400000ms referer=http://localhost:8888/tree/02-Python-para-Analisis-de-Datos-NumPy
[W 10:16:30.363 NotebookApp] 404 GET /api/contents/02-Python-para-Analisis-de-Datos-NumPy/01-NumPy%20Arreglos.ipynb?content=0&_=1634138074343 (127.0.0.1): No such file or directory: 02-Python-para-Analisis-de-Datos-NumPy/01-NumPy Arreglos.ipynb
[W 10:16:30.363 NotebookApp] No such file or directory: 02-Python-para-Analisis-de-Datos-NumPy/01-NumPy Arreglos.ipynb
[W 10:16:30.364 NotebookApp] 404 GET /api/contents/02-Python-para-Analisis-de-Datos-NumPy/01-NumPy%20Arreglos.ipynb?content=0&_=1634138074343 (127.0.0.1) 1.800000ms referer=http://localhost:8888/notebooks/02-Python-para-Analisis-de-Datos-NumPy/01-NumPy%20Arreglos.ipynb
[I 10:17:12.181 NotebookApp] The port 8888 is already in use, trying another port.
[I 10:17:12.182 NotebookApp] Serving notebooks from local directory: /home/g/Documents/AdminInfo/acc-python
[I 10:17:12.182 NotebookApp] Jupyter Notebook 6.4.3 is running at:
[I 10:17:12.182 NotebookApp] http://localhost:8889/?token=4bb7337c3aa491be36df9bfbd003114f1767dbb81dc1aa59
[I 10:17:12.182 NotebookApp]  or http://127.0.0.1:8889/?token=4bb7337c3aa491be36df9bfbd003114f1767dbb81dc1aa59
[I 10:17:12.182 NotebookApp] Use Control-C to stop this server and shut down all kernels (twice to skip confirmation).
[C 10:17:12.274 NotebookApp] 
    
    To access the notebook, open this file in a browser:
        file:///home/g/.local/share/jupyter/runtime/nbserver-4592-open.html
    Or copy and paste one of these URLs:
        http://localhost:8889/?token=4bb7337c3aa491be36df9bfbd003114f1767dbb81dc1aa59
     or http://127.0.0.1:8889/?token=4bb7337c3aa491be36df9bfbd003114f1767dbb81dc1aa59
/usr/lib/python3.9/json/encoder.py:257: UserWarning: date_default is deprecated since jupyter_client 7.0.0. Use jupyter_client.jsonutil.json_default.
  return _iterencode(o, 0)
[I 10:17:15.358 NotebookApp] Starting buffering for 60e59d63-754c-499d-afc2-817a7334a3c5:337992837d1c44fca6717b3c550c330b
