[I 10:08:39.773 NotebookApp] Serving notebooks from local directory: /home/g/Documents/AdminInfo/acc-python/12-Twitter-Analysis
[I 10:08:39.773 NotebookApp] Jupyter Notebook 6.4.4 is running at:
[I 10:08:39.774 NotebookApp] http://localhost:8888/?token=b1c9a5de2d4d7eebc63ee6b48340d7e768b1a07a1a6e6c58
[I 10:08:39.774 NotebookApp]  or http://127.0.0.1:8888/?token=b1c9a5de2d4d7eebc63ee6b48340d7e768b1a07a1a6e6c58
[I 10:08:39.774 NotebookApp] Use Control-C to stop this server and shut down all kernels (twice to skip confirmation).
[C 10:08:39.835 NotebookApp] 
    
    To access the notebook, open this file in a browser:
        file:///home/g/.local/share/jupyter/runtime/nbserver-4004-open.html
    Or copy and paste one of these URLs:
        http://localhost:8888/?token=b1c9a5de2d4d7eebc63ee6b48340d7e768b1a07a1a6e6c58
     or http://127.0.0.1:8888/?token=b1c9a5de2d4d7eebc63ee6b48340d7e768b1a07a1a6e6c58
/usr/lib/python3.9/json/encoder.py:257: UserWarning: date_default is deprecated since jupyter_client 7.0.0. Use jupyter_client.jsonutil.json_default.
  return _iterencode(o, 0)
[W 10:08:45.251 NotebookApp] Notebook 01-Twitter-Analisis-con-Tweepy-en-Python-SIN-CREDENCIALES.ipynb is not trusted
ERROR:asyncio:Exception in callback <TaskWakeupMethWrapper object at 0x7efcb3f23e80>(<Future finis...igin\r\n\r\n'>)
handle: <Handle <TaskWakeupMethWrapper object at 0x7efcb3f23e80>(<Future finis...igin\r\n\r\n'>)>
Traceback (most recent call last):
  File "/usr/lib/python3.9/asyncio/events.py", line 80, in _run
    self._context.run(self._callback, *self._args)
RuntimeError: Cannot enter into task <Task pending name='Task-5' coro=<HTTP1ServerConnection._server_request_loop() running at /home/g/.local/lib/python3.9/site-packages/tornado/http1connection.py:823> wait_for=<Future finished result=b'GET /kernel...rigin\r\n\r\n'> cb=[IOLoop.add_future.<locals>.<lambda>() at /home/g/.local/lib/python3.9/site-packages/tornado/ioloop.py:688]> while another task <Task pending name='Task-1' coro=<MultiKernelManager._async_start_kernel() running at /home/g/.local/lib/python3.9/site-packages/jupyter_client/multikernelmanager.py:186>> is being executed.
ERROR:asyncio:Exception in callback <TaskWakeupMethWrapper object at 0x7efcb80787f0>(<Future finis...igin\r\n\r\n'>)
handle: <Handle <TaskWakeupMethWrapper object at 0x7efcb80787f0>(<Future finis...igin\r\n\r\n'>)>
Traceback (most recent call last):
  File "/usr/lib/python3.9/asyncio/events.py", line 80, in _run
    self._context.run(self._callback, *self._args)
RuntimeError: Cannot enter into task <Task pending name='Task-8' coro=<HTTP1ServerConnection._server_request_loop() running at /home/g/.local/lib/python3.9/site-packages/tornado/http1connection.py:823> wait_for=<Future finished result=b'GET /api/co...rigin\r\n\r\n'> cb=[IOLoop.add_future.<locals>.<lambda>() at /home/g/.local/lib/python3.9/site-packages/tornado/ioloop.py:688]> while another task <Task pending name='Task-2' coro=<KernelManager._async_start_kernel() running at /home/g/.local/lib/python3.9/site-packages/jupyter_client/manager.py:336>> is being executed.
[I 10:08:46.219 NotebookApp] Kernel started: 55ac71ed-5e93-4690-9529-abb2f4118b98, name: python3
/usr/lib/python3.9/json/encoder.py:257: UserWarning: date_default is deprecated since jupyter_client 7.0.0. Use jupyter_client.jsonutil.json_default.
  return _iterencode(o, 0)
[W 10:10:09.580 NotebookApp] Notebook 01-Twitter-Analisis-con-Tweepy-en-Python.ipynb is not trusted
ERROR:asyncio:Exception in callback <TaskWakeupMethWrapper object at 0x7efcb3e52940>(<Future finished result=None>)
handle: <Handle <TaskWakeupMethWrapper object at 0x7efcb3e52940>(<Future finished result=None>)>
Traceback (most recent call last):
  File "/usr/lib/python3.9/asyncio/events.py", line 80, in _run
    self._context.run(self._callback, *self._args)
RuntimeError: Cannot enter into task <Task pending name='Task-7' coro=<HTTP1ServerConnection._server_request_loop() running at /home/g/.local/lib/python3.9/site-packages/tornado/http1connection.py:823> wait_for=<Future finished result=None> cb=[IOLoop.add_future.<locals>.<lambda>() at /home/g/.local/lib/python3.9/site-packages/tornado/ioloop.py:688]> while another task <Task pending name='Task-197' coro=<MappingKernelManager.start_kernel() running at /usr/lib/python3.9/site-packages/notebook/services/kernels/kernelmanager.py:176> cb=[IOLoop.add_future.<locals>.<lambda>() at /home/g/.local/lib/python3.9/site-packages/tornado/ioloop.py:695]> is being executed.
ERROR:asyncio:Exception in callback <TaskWakeupMethWrapper object at 0x7efcb35d59a0>(<Future finished result=None>)
handle: <Handle <TaskWakeupMethWrapper object at 0x7efcb35d59a0>(<Future finished result=None>)>
Traceback (most recent call last):
  File "/usr/lib/python3.9/asyncio/events.py", line 80, in _run
    self._context.run(self._callback, *self._args)
RuntimeError: Cannot enter into task <Task pending name='Task-1' coro=<HTTP1ServerConnection._server_request_loop() running at /home/g/.local/lib/python3.9/site-packages/tornado/http1connection.py:823> wait_for=<Future finished result=None> cb=[IOLoop.add_future.<locals>.<lambda>() at /home/g/.local/lib/python3.9/site-packages/tornado/ioloop.py:688]> while another task <Task pending name='Task-197' coro=<MappingKernelManager.start_kernel() running at /usr/lib/python3.9/site-packages/notebook/services/kernels/kernelmanager.py:176> cb=[IOLoop.add_future.<locals>.<lambda>() at /home/g/.local/lib/python3.9/site-packages/tornado/ioloop.py:695]> is being executed.
[I 10:10:11.498 NotebookApp] Kernel started: a9fd1fd1-0096-4618-b91a-8c63a6b554a4, name: python3
[W 10:10:12.063 NotebookApp] Notebook 02-Twitter-Analisis-con-Tweepy-en-Python-Ejercicio.ipynb is not trusted
[I 10:10:12.969 NotebookApp] Kernel started: e5ea3aa6-d39a-4cac-806c-51870b607247, name: python3
[I 10:10:13.621 NotebookApp] Starting buffering for a9fd1fd1-0096-4618-b91a-8c63a6b554a4:75174cfaf87b48a787225e4c9a724eca
[I 10:10:46.253 NotebookApp] Saving file at /01-Twitter-Analisis-con-Tweepy-en-Python-SIN-CREDENCIALES.ipynb
[I 10:12:12.987 NotebookApp] Saving file at /02-Twitter-Analisis-con-Tweepy-en-Python-Ejercicio.ipynb
[W 10:12:12.988 NotebookApp] Notebook 02-Twitter-Analisis-con-Tweepy-en-Python-Ejercicio.ipynb is not trusted
[W 10:15:37.094 NotebookApp] IOPub data rate exceeded.
    The notebook server will temporarily stop sending output
    to the client in order to avoid crashing it.
    To change this limit, set the config variable
    `--NotebookApp.iopub_data_rate_limit`.
    
    Current values:
    NotebookApp.iopub_data_rate_limit=1000000.0 (bytes/sec)
    NotebookApp.rate_limit_window=3.0 (secs)
    
[I 10:16:12.954 NotebookApp] Saving file at /02-Twitter-Analisis-con-Tweepy-en-Python-Ejercicio.ipynb
[W 10:16:12.955 NotebookApp] Notebook 02-Twitter-Analisis-con-Tweepy-en-Python-Ejercicio.ipynb is not trusted
[I 10:36:12.989 NotebookApp] Saving file at /02-Twitter-Analisis-con-Tweepy-en-Python-Ejercicio.ipynb
[W 10:36:12.991 NotebookApp] Notebook 02-Twitter-Analisis-con-Tweepy-en-Python-Ejercicio.ipynb is not trusted
[I 10:38:12.985 NotebookApp] Saving file at /02-Twitter-Analisis-con-Tweepy-en-Python-Ejercicio.ipynb
[W 10:38:12.987 NotebookApp] Notebook 02-Twitter-Analisis-con-Tweepy-en-Python-Ejercicio.ipynb is not trusted
[I 10:42:12.983 NotebookApp] Saving file at /02-Twitter-Analisis-con-Tweepy-en-Python-Ejercicio.ipynb
[W 10:42:12.984 NotebookApp] Notebook 02-Twitter-Analisis-con-Tweepy-en-Python-Ejercicio.ipynb is not trusted
[I 11:00:12.991 NotebookApp] Saving file at /02-Twitter-Analisis-con-Tweepy-en-Python-Ejercicio.ipynb
[W 11:00:12.991 NotebookApp] Notebook 02-Twitter-Analisis-con-Tweepy-en-Python-Ejercicio.ipynb is not trusted
[I 11:02:12.992 NotebookApp] Saving file at /02-Twitter-Analisis-con-Tweepy-en-Python-Ejercicio.ipynb
[W 11:02:12.993 NotebookApp] Notebook 02-Twitter-Analisis-con-Tweepy-en-Python-Ejercicio.ipynb is not trusted
[I 11:04:12.974 NotebookApp] Saving file at /02-Twitter-Analisis-con-Tweepy-en-Python-Ejercicio.ipynb
[W 11:04:12.976 NotebookApp] Notebook 02-Twitter-Analisis-con-Tweepy-en-Python-Ejercicio.ipynb is not trusted
[I 11:06:13.001 NotebookApp] Saving file at /02-Twitter-Analisis-con-Tweepy-en-Python-Ejercicio.ipynb
[W 11:06:13.002 NotebookApp] Notebook 02-Twitter-Analisis-con-Tweepy-en-Python-Ejercicio.ipynb is not trusted
[I 11:08:12.986 NotebookApp] Saving file at /02-Twitter-Analisis-con-Tweepy-en-Python-Ejercicio.ipynb
[W 11:08:12.988 NotebookApp] Notebook 02-Twitter-Analisis-con-Tweepy-en-Python-Ejercicio.ipynb is not trusted
[I 11:10:12.993 NotebookApp] Saving file at /02-Twitter-Analisis-con-Tweepy-en-Python-Ejercicio.ipynb
[W 11:10:12.994 NotebookApp] Notebook 02-Twitter-Analisis-con-Tweepy-en-Python-Ejercicio.ipynb is not trusted
[I 11:12:12.991 NotebookApp] Saving file at /02-Twitter-Analisis-con-Tweepy-en-Python-Ejercicio.ipynb
[W 11:12:12.992 NotebookApp] Notebook 02-Twitter-Analisis-con-Tweepy-en-Python-Ejercicio.ipynb is not trusted
[I 11:14:12.976 NotebookApp] Saving file at /02-Twitter-Analisis-con-Tweepy-en-Python-Ejercicio.ipynb
[W 11:14:12.977 NotebookApp] Notebook 02-Twitter-Analisis-con-Tweepy-en-Python-Ejercicio.ipynb is not trusted
[I 11:16:12.985 NotebookApp] Saving file at /02-Twitter-Analisis-con-Tweepy-en-Python-Ejercicio.ipynb
[W 11:16:12.987 NotebookApp] Notebook 02-Twitter-Analisis-con-Tweepy-en-Python-Ejercicio.ipynb is not trusted
[I 11:18:12.981 NotebookApp] Saving file at /02-Twitter-Analisis-con-Tweepy-en-Python-Ejercicio.ipynb
[W 11:18:12.982 NotebookApp] Notebook 02-Twitter-Analisis-con-Tweepy-en-Python-Ejercicio.ipynb is not trusted
[I 11:20:12.991 NotebookApp] Saving file at /02-Twitter-Analisis-con-Tweepy-en-Python-Ejercicio.ipynb
[W 11:20:12.992 NotebookApp] Notebook 02-Twitter-Analisis-con-Tweepy-en-Python-Ejercicio.ipynb is not trusted
[I 11:21:39.943 NotebookApp] Starting buffering for e5ea3aa6-d39a-4cac-806c-51870b607247:29d9fb2a7c384818b5b3ffaea87db6f9
[I 11:21:40.759 NotebookApp] Kernel restarted: e5ea3aa6-d39a-4cac-806c-51870b607247
[I 11:21:40.767 NotebookApp] Restoring connection for e5ea3aa6-d39a-4cac-806c-51870b607247:29d9fb2a7c384818b5b3ffaea87db6f9
[I 11:21:41.309 NotebookApp] Replaying 7 buffered messages
[I 11:22:12.959 NotebookApp] Saving file at /02-Twitter-Analisis-con-Tweepy-en-Python-Ejercicio.ipynb
[W 11:22:12.959 NotebookApp] Notebook 02-Twitter-Analisis-con-Tweepy-en-Python-Ejercicio.ipynb is not trusted
[I 11:24:12.978 NotebookApp] Saving file at /02-Twitter-Analisis-con-Tweepy-en-Python-Ejercicio.ipynb
[W 11:24:12.978 NotebookApp] Notebook 02-Twitter-Analisis-con-Tweepy-en-Python-Ejercicio.ipynb is not trusted
[I 11:26:12.990 NotebookApp] Saving file at /02-Twitter-Analisis-con-Tweepy-en-Python-Ejercicio.ipynb
[W 11:26:12.990 NotebookApp] Notebook 02-Twitter-Analisis-con-Tweepy-en-Python-Ejercicio.ipynb is not trusted
[I 11:28:12.990 NotebookApp] Saving file at /02-Twitter-Analisis-con-Tweepy-en-Python-Ejercicio.ipynb
[W 11:28:12.991 NotebookApp] Notebook 02-Twitter-Analisis-con-Tweepy-en-Python-Ejercicio.ipynb is not trusted
[I 11:30:12.988 NotebookApp] Saving file at /02-Twitter-Analisis-con-Tweepy-en-Python-Ejercicio.ipynb
[W 11:30:12.990 NotebookApp] Notebook 02-Twitter-Analisis-con-Tweepy-en-Python-Ejercicio.ipynb is not trusted
[I 11:32:13.002 NotebookApp] Saving file at /02-Twitter-Analisis-con-Tweepy-en-Python-Ejercicio.ipynb
[W 11:32:13.003 NotebookApp] Notebook 02-Twitter-Analisis-con-Tweepy-en-Python-Ejercicio.ipynb is not trusted
[I 11:32:25.623 NotebookApp] Saving file at /02-Twitter-Analisis-con-Tweepy-en-Python-Ejercicio.ipynb
[W 11:32:25.624 NotebookApp] Notebook 02-Twitter-Analisis-con-Tweepy-en-Python-Ejercicio.ipynb is not trusted
